Workbook

Sheet 项目特征
A1: 规模计数时机 | C1: 项目完成及运维阶段 | D1: =IF(项目特征!C1='模板使用说明&基础参数'!H51,'模板使用说明&基础参数'!I51,IF(项目特征!C1='模板使用说明&基础参数'!H52,'模板使用说明&基础参数'!I52,IF(项目特征!C1='模板使用说明&基础参数'!H53,'模板使用说明&基础参数'!I53,IF(项目特征!C1='模板使用说明&基础参数'!H54,'模板使用说明&基础参数'!I54,1)))) -> 1 | G1: 填写说明 | H1: 1.评估的是已完成的需求工单，计数时机缺省选择“项目完成及运维阶段”，对于工单评估不允许选其他值；
A2: 应用类型 | C2: 电信类系统 | D2: =IF(C2="","",IF(C2='模板使用说明&基础参数'!G10,'模板使用说明&基础参数'!I10,IF(C2='模板使用说明&基础参数'!G11,'模板使用说明&基础参数'!I11,1))) -> 10.74 | H2: 2.应用类型主要区分电信类系统（B域、O域电信行业特有的业务运营/支撑类系统）和非电信类系统（M域非电信行业特有的系统，如人力资源、绩效考核、项目管理、合同管理、综合事务管理、供应链管理等系统）；
A3: 质量特性 | B3: 分布式处理 | C3: 通过网络进行客户端/服务器及网络基础应用分布处理和传输 | D3: =IF(C3='模板使用说明&基础参数'!H20,'模板使用说明&基础参数'!I20,IF(C3='模板使用说明&基础参数'!H21,'模板使用说明&基础参数'!I21,IF(C3='模板使用说明&基础参数'!H22,'模板使用说明&基础参数'!I22,0))) -> 0 | H3: 3.质量特性、完整性级别、开发语言、开发团队背景通常无特殊要求下都选择缺省值；
B4: 性能 | C4: 应答时间或处理率对高峰时间或所有业务时间来说都很重要，存在对连动系统结束处理时间的限制 | D4: =IF(C4='模板使用说明&基础参数'!H23,'模板使用说明&基础参数'!I23,IF(C4='模板使用说明&基础参数'!H24,'模板使用说明&基础参数'!I24,IF(C4='模板使用说明&基础参数'!H25,'模板使用说明&基础参数'!I25,0))) -> 0 | H4: 4.纯粹非功能需求工单按非功能需求估算模板来评估，如非功能需求仅为需求工单的部分内容，按功能需求估算模板来评估，非功能类需求包含在功能需求开发中不单独评估；
B5: 可靠性 | C5: 发生故障时带来较多不便或经济损失 | D5: =IF(C5='模板使用说明&基础参数'!H26,'模板使用说明&基础参数'!I26,IF(C5='模板使用说明&基础参数'!H27,'模板使用说明&基础参数'!I27,IF(C5='模板使用说明&基础参数'!H28,'模板使用说明&基础参数'!I28,0))) -> 0 | H5: 5.规模估算表中，对于已完成的需求工单，规模估算方法缺省选择“估算功能点”，不允许选其他值；
B6: 多重站点 | C6: 在设计阶段需要考虑不同站点的相似硬件或软件环境下运行需求 | D6: =IF(C6='模板使用说明&基础参数'!H29,'模板使用说明&基础参数'!I29,IF(C6='模板使用说明&基础参数'!H30,'模板使用说明&基础参数'!I30,IF(C6='模板使用说明&基础参数'!H31,'模板使用说明&基础参数'!I31,0))) -> 0 | H6: 6.规模估算表中，重用程度的判断规则，参见下表说明，如果所提供的文档中缺少可以判断功能重用程度的数据或相应的描述，则按“中”等复用处理；
A7: 完整性级别 | C7: 没有明确的完整性级别或等级为C/D | D7: =IF(C7='模板使用说明&基础参数'!H46,'模板使用说明&基础参数'!I46,IF(C7='模板使用说明&基础参数'!H47,'模板使用说明&基础参数'!I47,IF(C7='模板使用说明&基础参数'!H48,'模板使用说明&基础参数'!I48,1))) -> 1 | H7: 7.规模估算表中带有公式，如果要插入行，请先复制一个带公式的空行，再插入复制行，避免结果出错；
A8: 开发语言 | C8: JAVA、C++、C#及其他同级别语言/平台 | D8: =IF(C8='模板使用说明&基础参数'!H35,'模板使用说明&基础参数'!I35,IF(C8='模板使用说明&基础参数'!H36,'模板使用说明&基础参数'!I36,IF(C8='模板使用说明&基础参数'!H37,'模板使用说明&基础参数'!I37,1))) -> 1 | H8: 8.每个需求工单填写一个估算表，表名称：需求单号-需求概述-功能需求工作量评估表；
A9: 开发团队背景 | C9: 为本行业开发过类似的软件 | D9: =IF(C9='模板使用说明&基础参数'!H41,'模板使用说明&基础参数'!I41,IF(C9='模板使用说明&基础参数'!H42,'模板使用说明&基础参数'!I42,IF(C9='模板使用说明&基础参数'!H43,'模板使用说明&基础参数'!I43,1))) -> 0.8
G16: 重用程度 | H16: 判断规则 | I16: 对应值
G17: 低 | H17: 如果数据功能的数据元素类型改变≥50%，则重用程度为低； | I17: 1
H18: 如果事务功能的主要处理逻辑发生变化，数据元素类型，访问或维护的逻辑文件数改变≥50%，则重用程度为低。
G19: 中 | H19: 如果数据功能的数据元素类型改变在20%~50%（含20%且不包含50%），则重用程度为中； | I19: 2/3
H20: 如果事务功能的主要处理逻辑发生变化，数据元素类型，访问或维护的逻辑文件数改变在20%~50%（含20%且不包含50%），则重用程度为中。
G21: 高 | H21: 如果数据功能的数据元素类型改变<20%，则重用程度为高； | I21: 1/3
H22: 如果事务功能的主要处理逻辑未发生变化，且数据元素类型，访问或维护的逻辑文件数改变<20%，则重用程度为高。

Sheet 规模估算
A1: 规模估算方法 | C1: 估算功能点 | D1: 项目编号
A2: 功能点合计(FP) | C2: =SUM(I6:I100009) -> 3665 | D2: 厂商名称
A3: 调整后功能点(FP) | C3: =ROUND(SUM(L6:L100009),2) -> 977.33 | L3: =C3 -> 977.33
A4: 填写说明 | B4: 手工填写 | C4: 手工填写 | D4: 手工填写 | E4: 手工填写 | F4: 手工填写，对功能点计数项的补充描述，包含修改内容描述 | G4: 手工必填，根据需求说明按功能点方法识别出基本的功能点计数项 | H4: 下拉选择，按功能点方法标准判断 | I4: 不需填写，公式计算 | J4: 下拉选择，参考“项目特征”中的重用度判断规则说明 | K4: 下拉选择，分为新增、修改、删除 | L4: 不需填写，公式计算 | M4: 可选填写，对本条工作项内容的补充说明 | N4: 填报人员不需填写，审核人员将L列评估结果以值拷贝的方式复制到N列； | O4: 可选填写，对本条工作项内容的审核说明
A5: 编号 | B5: 子系统 | C5: 一级模块 | D5: 二级模块 | E5: 三级模块 | F5: 功能项描述 | G5: 功能点计数项名称 | H5: 类别 | I5: UFP | J5: 重用程度 | K5: 修改类型 | L5: US | M5: 填报备注 | N5: 填报规模 | O5: 审核备注
A6: 1 | B6: 产商品中心 | C6: 营销活动配置 | D6: 营销活动配置管理 | E6: 营销活动配置管理 | F6: 5G金币营销活动档位信息在产商品中心中维护和存储，支持业务人员对数据做维护管理，数据主要字段包括：档位类型、是否启用、启用状态、档位编码、活动编码、排序号等；同时数据提供给营销活动配置管理业务引用。本次涉及调整修改内容为调整相关字段以适配营销活动业务变更需求。 | G6: 5G金币营销活动档位信息 | H6: ILF | I6: =IF(H6="ILF",IF($C$1="预估功能点",'模板使用说明&基础参数'!$E$15,7),IF(H6="EIF",IF($C$1="预估功能点",'模板使用说明&基础参数'!$E$16,5),IF(H6="EI",IF($C$1="预估功能点",'模板使用说明&基础参数'!$E$17,'模板使用说明&基础参数'!$E$24),IF(H6="EO",IF($C$1="预估功能点",'模板使用说明&基础参数'!$E$18,'模板使用说明&基础参数'!$E$25),IF(H6="EQ",IF($C$1="预估功能点",'模板使用说明&基础参数'!$E$19,'模板使用说明&基础参数'!$E$26),""))))) -> 7 | J6: 高 | K6: 修改 | L6: =IF(I6="","",IF(J6="高",IF(K6="删除",I6*'模板使用说明&基础参数'!$E$5*'模板使用说明&基础参数'!$E$12,IF(K6="修改",I6*'模板使用说明&基础参数'!$E$5*'模板使用说明&基础参数'!$E$11,I6*'模板使用说明&基础参数'!$E$5*'模板使用说明&基础参数'!$E$10)),IF(J6="中",IF(K6="删除",I6*'模板使用说明&基础参数'!$E$6*'模板使用说明&基础参数'!$E$12,IF(K6="修改",I6*'模板使用说明&基础参数'!$E$6*'模板使用说明&基础参数'!$E$11,I6*'模板使用说明&基础参数'!$E$6*'模板使用说明&基础参数'!$E$10)),IF(K6="删除",I6*'模板使用说明&基础参数'!$E$7*'模板使用说明&基础参数'!$E$12,IF(K6="修改",I6*'模板使用说明&基础参数'!$E$7*'模板使用说明&基础参数'!$E$11,I6*'模板使用说明&基础参数'!$E$7*'模板使用说明&基础参数'!$E$10))))) -> 1.8666667
A7: 2 | B7: 产商品中心 | C7: 营销活动配置 | D7: 营销活动配置管理 | E7: 营销活动配置管理 | F7: 作为业务人员，当需要查询5G金币营销活动档位信息时，能够通过此功能查出地市编码、渠道类型、用户标识、服务号码、活动编号等信息，以便于快速获取营销活动相关信息。本次涉及调整修改内容为优化5G金币营销活动档位信息查询功能。 | G7: 5G金币营销活动档位信息查询 | H7: EQ | I7: =IF(H7="ILF",IF($C$1="预估功能点",'模板使用说明&基础参数'!$E$15,7),IF(H7="EIF",IF($C$1="预估功能点",'模板使用说明&基础参数'!$E$16,5),IF(H7="EI",IF($C$1="预估功能点",'模板使用说明&基础参数'!$E$17,'模板使用说明&基础参数'!$E$24),IF(H7="EO",IF($C$1="预估功能点",'模板使用说明&基础参数'!$E$18,'模板使用说明&基础参数'!$E$25),IF(H7="EQ",IF($C$1="预估功能点",'模板使用说明&基础参数'!$E$19,'模板使用说明&基础参数'!$E$26),""))))) -> 4 | J7: 高 | K7: 修改 | L7: =IF(I7="","",IF(J7="高",IF(K7="删除",I7*'模板使用说明&基础参数'!$E$5*'模板使用说明&基础参数'!$E$12,IF(K7="修改",I7*'模板使用说明&基础参数'!$E$5*'模板使用说明&基础参数'!$E$11,I7*'模板使用说明&基础参数'!$E$5*'模板使用说明&基础参数'!$E$10)),IF(J7="中",IF(K7="删除",I7*'模板使用说明&基础参数'!$E$6*'模板使用说明&基础参数'!$E$12,IF(K7="修改",I7*'模板使用说明&基础参数'!$E$6*'模板使用说明&基础参数'!$E$11,I7*'模板使用说明&基础参数'!$E$6*'模板使用说明&基础参数'!$E$10)),IF(K7="删除",I7*'模板使用说明&基础参数'!$E$7*'模板使用说明&基础参数'!$E$12,IF(K7="修改",I7*'模板使用说明&基础参数'!$E$7*'模板使用说明&基础参数'!$E$11,I7*'模板使用说明&基础参数'!$E$7*'模板使用说明&基础参数'!$E$10))))) -> 1.0666667
A8: 3 | B8: 产商品中心 | C8: 营销活动配置 | D8: 营销活动配置管理 | E8: 营销活动配置管理 | F8: 作为业务人员，当需要删除5G金币营销活动档位信息时，能够通过此功能删除5G金币营销活动档位信息，以便于清理失效的营销活动配置数据。本次涉及调整修改内容为新增5G金币营销活动档位信息删除处理逻辑，支持通过5G金币营销活动档位信息编号删除指定记录。 | G8: 5G金币营销活动档位信息删除 | H8: EI | I8: =IF(H8="ILF",IF($C$1="预估功能点",'模板使用说明&基础参数'!$E$15,7),IF(H8="EIF",IF($C$1="预估功能点",'模板使用说明&基础参数'!$E$16,5),IF(H8="EI",IF($C$1="预估功能点",'模板使用说明&基础参数'!$E$17,'模板使用说明&基础参数'!$E$24),IF(H8="EO",IF($C$1="预估功能点",'模板使用说明&基础参数'!$E$18,'模板使用说明&基础参数'!$E$25),IF(H8="EQ",IF($C$1="预估功能点",'模板使用说明&基础参数'!$E$19,'模板使用说明&基础参数'!$E$26),""))))) -> 4 | J8: 高 | K8: 修改 | L8: =IF(I8="","",IF(J8="高",IF(K8="删除",I8*'模板使用说明&基础参数'!$E$5*'模板使用说明&基础参数'!$E$12,IF(K8="修改",I8*'模板使用说明&基础参数'!$E$5*'模板使用说明&基础参数'!$E$11,I8*'模板使用说明&基础参数'!$E$5*'模板使用说明&基础参数'!$E$10)),IF(J8="中",IF(K8="删除",I8*'模板使用说明&基础参数'!$E$6*'模板使用说明&基础参数'!$E$12,IF(K8="修改",I8*'模板使用说明&基础参数'!$E$6*'模板使用说明&基础参数'!$E$11,I8*'模板使用说明&基础参数'!$E$6*'模板使用说明&基础参数'!$E$10)),IF(K8="删除",I8*'模板使用说明&基础参数'!$E$7*'模板使用说明&基础参数'!$E$12,IF(K8="修改",I8*'模板使用说明&基础参数'!$E$7*'模板使用说明&基础参数'!$E$11,I8*'模板使用说明&基础参数'!$E$7*'模板使用说明&基础参数'!$E$10))))) -> 1.0666667
A9: 4 | B9: 产商品中心 | C9: 营销活动配置 | D9: 营销活动配置管理 | E9: 营销活动配置管理 | F9: 作为业务人员，当需要新增5G金币营销活动档位信息时，能够通过此功能新增5G金币营销活动档位信息，以便于及时配置营销活动相关数据。本次涉及调整修改内容为新增5G金币营销活动档位信息新增处理逻辑，支持编号、名称、类型、状态、操作人员等内容的录入。 | G9: 5G金币营销活动档位信息新增 | H9: EI | I9: =IF(H9="ILF",IF($C$1="预估功能点",'模板使用说明&基础参数'!$E$15,7),IF(H9="EIF",IF($C$1="预估功能点",'模板使用说明&基础参数'!$E$16,5),IF(H9="EI",IF($C$1="预估功能点",'模板使用说明&基础参数'!$E$17,'模板使用说明&基础参数'!$E$24),IF(H9="EO",IF($C$1="预估功能点",'模板使用说明&基础参数'!$E$18,'模板使用说明&基础参数'!$E$25),IF(H9="EQ",IF($C$1="预估功能点",'模板使用说明&基础参数'!$E$19,'模板使用说明&基础参数'!$E$26),""))))) -> 4 | J9: 高 | K9: 修改 | L9: =IF(I9="","",IF(J9="高",IF(K9="删除",I9*'模板使用说明&基础参数'!$E$5*'模板使用说明&基础参数'!$E$12,IF(K9="修改",I9*'模板使用说明&基础参数'!$E$5*'模板使用说明&基础参数'!$E$11,I9*'模板使用说明&基础参数'!$E$5*'模板使用说明&基础参数'!$E$10)),IF(J9="中",IF(K9="删除",I9*'模板使用说明&基础参数'!$E$6*'模板使用说明&基础参数'!$E$12,IF(K9="修改",I9*'模板使用说明&基础参数'!$E$6*'模板使用说明&基础参数'!$E$11,I9*'模板使用说明&基础参数'!$E$6*'模板使用说明&基础参数'!$E$10)),IF(K9="删除",I9*'模板使用说明&基础参数'!$E$7*'模板使用说明&基础参数'!$E$12,IF(K9="修改",I9*'模板使用说明&基础参数'!$E$7*'模板使用说明&基础参数'!$E$11,I9*'模板使用说明&基础参数'!$E$7*'模板使用说明&基础参数'!$E$10))))) -> 1.0666667
A10: 5 | B10: 产商品中心 | C10: 营销活动配置 | D10: 营销活动配置管理 | E10: 营销活动配置管理 | F10: 作为业务人员，当需要修改5G金币营销活动档位信息时，能够通过此功能修改5G金币营销活动档位信息，以便于及时更新营销活动相关数据。本次涉及调整修改内容为调整渠道类型、用户标识、服务号码、工单号等业务处理逻辑以满足营销活动配置管理需求。 | G10: 5G金币营销活动档位信息修改 | H10: EI | I10: =IF(H10="ILF",IF($C$1="预估功能点",'模板使用说明&基础参数'!$E$15,7),IF(H10="EIF",IF($C$1="预估功能点",'模板使用说明&基础参数'!$E$16,5),IF(H10="EI",IF($C$1="预估功能点",'模板使用说明&基础参数'!$E$17,'模板使用说明&基础参数'!$E$24),IF(H10="EO",IF($C$1="预估功能点",'模板使用说明&基础参数'!$E$18,'模板使用说明&基础参数'!$E$25),IF(H10="EQ",IF($C$1="预估功能点",'模板使用说明&基础参数'!$E$19,'模板使用说明&基础参数'!$E$26),""))))) -> 4 | J10: 高 | K10: 修改 | L10: =IF(I10="","",IF(J10="高",IF(K10="删除",I10*'模板使用说明&基础参数'!$E$5*'模板使用说明&基础参数'!$E$12,IF(K10="修改",I10*'模板使用说明&基础参数'!$E$5*'模板使用说明&基础参数'!$E$11,I10*'模板使用说明&基础参数'!$E$5*'模板使用说明&基础参数'!$E$10)),IF(J10="中",IF(K10="删除",I10*'模板使用说明&基础参数'!$E$6*'模板使用说明&基础参数'!$E$12,IF(K10="修改",I10*'模板使用说明&基础参数'!$E$6*'模板使用说明&基础参数'!$E$11,I10*'模板使用说明&基础参数'!$E$6*'模板使用说明&基础参数'!$E$10)),IF(K10="删除",I10*'模板使用说明&基础参数'!$E$7*'模板使用说明&基础参数'!$E$12,IF(K10="修改",I10*'模板使用说明&基础参数'!$E$7*'模板使用说明&基础参数'!$E$11,I10*'模板使用说明&基础参数'!$E$7*'模板使用说明&基础参数'!$E$10))))) -> 1.0666667
A11: 6 | B11: 产商品中心 | C11: 营销活动配置 | D11: 营销活动配置管理 | E11: 营销活动配置管理 | F11: 5G金币营销活动合约信息在产商品中心中维护和存储，支持业务人员对数据做维护管理，数据主要字段包括：地市编码、渠道类型、用户标识、服务号码、活动编号、方式编号、营业厅编号、操作员ID、工单号、订单编号等；同时数据提供给营销活动配置管理业务引用。本次涉及调整修改内容为调整相关字段以适配营销活动业务变更需求。 | G11: 5G金币营销活动合约信息 | H11: ILF | I11: =IF(H11="ILF",IF($C$1="预估功能点",'模板使用说明&基础参数'!$E$15,7),IF(H11="EIF",IF($C$1="预估功能点",'模板使用说明&基础参数'!$E$16,5),IF(H11="EI",IF($C$1="预估功能点",'模板使用说明&基础参数'!$E$17,'模板使用说明&基础参数'!$E$24),IF(H11="EO",IF($C$1="预估功能点",'模板使用说明&基础参数'!$E$18,'模板使用说明&基础参数'!$E$25),IF(H11="EQ",IF($C$1="预估功能点",'模板使用说明&基础参数'!$E$19,'模板使用说明&基础参数'!$E$26),""))))) -> 7 | J11: 高 | K11: 修改 | L11: =IF(I11="","",IF(J11="高",IF(K11="删除",I11*'模板使用说明&基础参数'!$E$5*'模板使用说明&基础参数'!$E$12,IF(K11="修改",I11*'模板使用说明&基础参数'!$E$5*'模板使用说明&基础参数'!$E$11,I11*'模板使用说明&基础参数'!$E$5*'模板使用说明&基础参数'!$E$10)),IF(J11="中",IF(K11="删除",I11*'模板使用说明&基础参数'!$E$6*'模板使用说明&基础参数'!$E$12,IF(K11="修改",I11*'模板使用说明&基础参数'!$E$6*'模板使用说明&基础参数'!$E$11,I11*'模板使用说明&基础参数'!$E$6*'模板使用说明&基础参数'!$E$10)),IF(K11="删除",I11*'模板使用说明&基础参数'!$E$7*'模板使用说明&基础参数'!$E$12,IF(K11="修改",I11*'模板使用说明&基础参数'!$E$7*'模板使用说明&基础参数'!$E$11,I11*'模板使用说明&基础参数'!$E$7*'模板使用说明&基础参数'!$E$10))))) -> 1.8666667
A12: 7 | B12: 产商品中心 | C12: 营销活动配置 | D12: 营销活动配置管理 | E12: 营销活动配置管理 | F12: 作为业务人员，当需要查询5G金币营销活动合约信息时，能够通过此功能查出地市编码、渠道类型、用户标识、服务号码、活动编号等信息，以便于快速获取营销活动相关信息。本次涉及调整修改内容为优化5G金币营销活动合约信息查询功能。 | G12: 5G金币营销活动合约信息查询 | H12: EQ | I12: =IF(H12="ILF",IF($C$1="预估功能点",'模板使用说明&基础参数'!$E$15,7),IF(H12="EIF",IF($C$1="预估功能点",'模板使用说明&基础参数'!$E$16,5),IF(H12="EI",IF($C$1="预估功能点",'模板使用说明&基础参数'!$E$17,'模板使用说明&基础参数'!$E$24),IF(H12="EO",IF($C$1="预估功能点",'模板使用说明&基础参数'!$E$18,'模板使用说明&基础参数'!$E$25),IF(H12="EQ",IF($C$1="预估功能点",'模板使用说明&基础参数'!$E$19,'模板使用说明&基础参数'!$E$26),""))))) -> 4 | J12: 高 | K12: 修改 | L12: =IF(I12="","",IF(J12="高",IF(K12="删除",I12*'模板使用说明&基础参数'!$E$5*'模板使用说明&基础参数'!$E$12,IF(K12="修改",I12*'模板使用说明&基础参数'!$E$5*'模板使用说明&基础参数'!$E$11,I12*'模板使用说明&基础参数'!$E$5*'模板使用说明&基础参数'!$E$10)),IF(J12="中",IF(K12="删除",I12*'模板使用说明&基础参数'!$E$6*'模板使用说明&基础参数'!$E$12,IF(K12="修改",I12*'模板使用说明&基础参数'!$E$6*'模板使用说明&基础参数'!$E$11,I12*'模板使用说明&基础参数'!$E$6*'模板使用说明&基础参数'!$E$10)),IF(K12="删除",I12*'模板使用说明&基础参数'!$E$7*'模板使用说明&基础参数'!$E$12,IF(K12="修改",I12*'模板使用说明&基础参数'!$E$7*'模板使用说明&基础参数'!$E$11,I12*'模板使用说明&基础参数'!$E$7*'模板使用说明&基础参数'!$E$10))))) -> 1.0666667
A13: 8 | B13: 产商品中心 | C13: 营销活动配置 | D13: 营销活动配置管理 | E13: 营销活动配置管理 | F13: 作为业务人员，当需要删除5G金币营销活动合约信息时，能够通过此功能删除5G金币营销活动合约信息，以便于清理失效的营销活动配置数据。本次涉及调整修改内容为新增5G金币营销活动合约信息删除处理逻辑，支持通过5G金币营销活动合约信息编号删除指定记录。 | G13: 5G金币营销活动合约信息删除 | H13: EI | I13: =IF(H13="ILF",IF($C$1="预估功能点",'模板使用说明&基础参数'!$E$15,7),IF(H13="EIF",IF($C$1="预估功能点",'模板使用说明&基础参数'!$E$16,5),IF(H13="EI",IF($C$1="预估功能点",'模板使用说明&基础参数'!$E$17,'模板使用说明&基础参数'!$E$24),IF(H13="EO",IF($C$1="预估功能点",'模板使用说明&基础参数'!$E$18,'模板使用说明&基础参数'!$E$25),IF(H13="EQ",IF($C$1="预估功能点",'模板使用说明&基础参数'!$E$19,'模板使用说明&基础参数'!$E$26),""))))) -> 4 | J13: 高 | K13: 修改 | L13: =IF(I13="","",IF(J13="高",IF(K13="删除",I13*'模板使用说明&基础参数'!$E$5*'模板使用说明&基础参数'!$E$12,IF(K13="修改",I13*'模板使用说明&基础参数'!$E$5*'模板使用说明&基础参数'!$E$11,I13*'模板使用说明&基础参数'!$E$5*'模板使用说明&基础参数'!$E$10)),IF(J13="中",IF(K13="删除",I13*'模板使用说明&基础参数'!$E$6*'模板使用说明&基础参数'!$E$12,IF(K13="修改",I13*'模板使用说明&基础参数'!$E$6*'模板使用说明&基础参数'!$E$11,I13*'模板使用说明&基础参数'!$E$6*'模板使用说明&基础参数'!$E$10)),IF(K13="删除",I13*'模板使用说明&基础参数'!$E$7*'模板使用说明&基础参数'!$E$12,IF(K13="修改",I13*'模板使用说明&基础参数'!$E$7*'模板使用说明&基础参数'!$E$11,I13*'模板使用说明&基础参数'!$E$7*'模板使用说明&基础参数'!$E$10))))) -> 1.0666667
A14: 9 | B14: 产商品中心 | C14: 营销活动配置 | D14: 营销活动配置管理 | E14: 营销活动配置管理 | F14: 作为业务人员，当需要新增5G金币营销活动合约信息时，能够通过此功能新增5G金币营销活动合约信息，以便于及时配置营销活动相关数据。本次涉及调整修改内容为新增5G金币营销活动合约信息新增处理逻辑，支持编号、名称、类型、状态、操作人员等内容的录入。 | G14: 5G金币营销活动合约信息新增 | H14: EI | I14: =IF(H14="ILF",IF($C$1="预估功能点",'模板使用说明&基础参数'!$E$15,7),IF(H14="EIF",IF($C$1="预估功能点",'模板使用说明&基础参数'!$E$16,5),IF(H14="EI",IF($C$1="预估功能点",'模板使用说明&基础参数'!$E$17,'模板使用说明&基础参数'!$E$24),IF(H14="EO",IF($C$1="预估功能点",'模板使用说明&基础参数'!$E$18,'模板使用说明&基础参数'!$E$25),IF(H14="EQ",IF($C$1="预估功能点",'模板使用说明&基础参数'!$E$19,'模板使用说明&基础参数'!$E$26),""))))) -> 4 | J14: 高 | K14: 修改 | L14: =IF(I14="","",IF(J14="高",IF(K14="删除",I14*'模板使用说明&基础参数'!$E$5*'模板使用说明&基础参数'!$E$12,IF(K14="修改",I14*'模板使用说明&基础参数'!$E$5*'模板使用说明&基础参数'!$E$11,I14*'模板使用说明&基础参数'!$E$5*'模板使用说明&基础参数'!$E$10)),IF(J14="中",IF(K14="删除",I14*'模板使用说明&基础参数'!$E$6*'模板使用说明&基础参数'!$E$12,IF(K14="修改",I14*'模板使用说明&基础参数'!$E$6*'模板使用说明&基础参数'!$E$11,I14*'模板使用说明&基础参数'!$E$6*'模板使用说明&基础参数'!$E$10)),IF(K14="删除",I14*'模板使用说明&基础参数'!$E$7*'模板使用说明&基础参数'!$E$12,IF(K14="修改",I14*'模板使用说明&基础参数'!$E$7*'模板使用说明&基础参数'!$E$11,I14*'模板使用说明&基础参数'!$E$7*'模板使用说明&基础参数'!$E$10))))) -> 1.0666667
A15: 10 | B15: 产商品中心 | C15: 营销活动配置 | D15: 营销活动配置管理 | E15: 营销活动配置管理 | F15: 作为业务人员，当需要修改5G金币营销活动合约信息时，能够通过此功能修改5G金币营销活动合约信息，以便于及时更新营销活动相关数据。本次涉及调整修改内容为调整渠道类型、用户标识、服务号码、工单号等业务处理逻辑以满足营销活动配置管理需求。 | G15: 5G金币营销活动合约信息修改 | H15: EI | I15: =IF(H15="ILF",IF($C$1="预估功能点",'模板使用说明&基础参数'!$E$15,7),IF(H15="EIF",IF($C$1="预估功能点",'模板使用说明&基础参数'!$E$16,5),IF(H15="EI",IF($C$1="预估功能点",'模板使用说明&基础参数'!$E$17,'模板使用说明&基础参数'!$E$24),IF(H15="EO",IF($C$1="预估功能点",'模板使用说明&基础参数'!$E$18,'模板使用说明&基础参数'!$E$25),IF(H15="EQ",IF($C$1="预估功能点",'模板使用说明&基础参数'!$E$19,'模板使用说明&基础参数'!$E$26),""))))) -> 4 | J15: 高 | K15: 修改 | L15: =IF(I15="","",IF(J15="高",IF(K15="删除",I15*'模板使用说明&基础参数'!$E$5*'模板使用说明&基础参数'!$E$12,IF(K15="修改",I15*'模板使用说明&基础参数'!$E$5*'模板使用说明&基础参数'!$E$11,I15*'模板使用说明&基础参数'!$E$5*'模板使用说明&基础参数'!$E$10)),IF(J15="中",IF(K15="删除",I15*'模板使用说明&基础参数'!$E$6*'模板使用说明&基础参数'!$E$12,IF(K15="修改",I15*'模板使用说明&基础参数'!$E$6*'模板使用说明&基础参数'!$E$11,I15*'模板使用说明&基础参数'!$E$6*'模板使用说明&基础参数'!$E$10)),IF(K15="删除",I15*'模板使用说明&基础参数'!$E$7*'模板使用说明&基础参数'!$E$12,IF(K15="修改",I15*'模板使用说明&基础参数'!$E$7*'模板使用说明&基础参数'!$E$11,I15*'模板使用说明&基础参数'!$E$7*'模板使用说明&基础参数'!$E$10))))) -> 1.0666667
A16: 11 | B16: 产商品中心 | C16: 营销活动配置 | D16: 营销活动配置管理 | E16: 营销活动配置管理 | F16: 5G金币营销活动渠道信息在产商品中心中维护和存储，支持业务人员对数据做维护管理，数据主要字段包括：渠道分组、编码、渠道状态、区县编码、状态、渠道类型等；同时数据提供给营销活动配置管理业务引用。本次涉及调整修改内容为调整相关字段以适配营销活动业务变更需求。 | G16: 5G金币营销活动渠道信息 | H16: ILF | I16: =IF(H16="ILF",IF($C$1="预估功能点",'模板使用说明&基础参数'!$E$15,7),IF(H16="EIF",IF($C$1="预估功能点",'模板使用说明&基础参数'!$E$16,5),IF(H16="EI",IF($C$1="预估功能点",'模板使用说明&基础参数'!$E$17,'模板使用说明&基础参数'!$E$24),IF(H16="EO",IF($C$1="预估功能点",'模板使用说明&基础参数'!$E$18,'模板使用说明&基础参数'!$E$25),IF(H16="EQ",IF($C$1="预估功能点",'模板使用说明&基础参数'!$E$19,'模板使用说明&基础参数'!$E$26),""))))) -> 7 | J16: 高 | K16: 修改 | L16: =IF(I16="","",IF(J16="高",IF(K16="删除",I16*'模板使用说明&基础参数'!$E$5*'模板使用说明&基础参数'!$E$12,IF(K16="修改",I16*'模板使用说明&基础参数'!$E$5*'模板使用说明&基础参数'!$E$11,I16*'模板使用说明&基础参数'!$E$5*'模板使用说明&基础参数'!$E$10)),IF(J16="中",IF(K16="删除",I16*'模板使用说明&基础参数'!$E$6*'模板使用说明&基础参数'!$E$12,IF(K16="修改",I16*'模板使用说明&基础参数'!$E$6*'模板使用说明&基础参数'!$E$11,I16*'模板使用说明&基础参数'!$E$6*'模板使用说明&基础参数'!$E$10)),IF(K16="删除",I16*'模板使用说明&基础参数'!$E$7*'模板使用说明&基础参数'!$E$12,IF(K16="修改",I16*'模板使用说明&基础参数'!$E$7*'模板使用说明&基础参数'!$E$11,I16*'模板使用说明&基础参数'!$E$7*'模板使用说明&基础参数'!$E$10))))) -> 1.8666667
A17: 12 | B17: 产商品中心 | C17: 营销活动配置 | D17: 营销活动配置管理 | E17: 营销活动配置管理 | F17: 作为业务人员，当需要查询5G金币营销活动渠道信息时，能够通过此功能查出地市编码、渠道类型、用户标识、服务号码、活动编号等信息，以便于快速获取营销活动相关信息。本次涉及调整修改内容为优化5G金币营销活动渠道信息查询功能。 | G17: 5G金币营销活动渠道信息查询 | H17: EQ | I17: =IF(H17="ILF",IF($C$1="预估功能点",'模板使用说明&基础参数'!$E$15,7),IF(H17="EIF",IF($C$1="预估功能点",'模板使用说明&基础参数'!$E$16,5),IF(H17="EI",IF($C$1="预估功能点",'模板使用说明&基础参数'!$E$17,'模板使用说明&基础参数'!$E$24),IF(H17="EO",IF($C$1="预估功能点",'模板使用说明&基础参数'!$E$18,'模板使用说明&基础参数'!$E$25),IF(H17="EQ",IF($C$1="预估功能点",'模板使用说明&基础参数'!$E$19,'模板使用说明&基础参数'!$E$26),""))))) -> 4 | J17: 高 | K17: 修改 | L17: =IF(I17="","",IF(J17="高",IF(K17="删除",I17*'模板使用说明&基础参数'!$E$5*'模板使用说明&基础参数'!$E$12,IF(K17="修改",I17*'模板使用说明&基础参数'!$E$5*'模板使用说明&基础参数'!$E$11,I17*'模板使用说明&基础参数'!$E$5*'模板使用说明&基础参数'!$E$10)),IF(J17="中",IF(K17="删除",I17*'模板使用说明&基础参数'!$E$6*'模板使用说明&基础参数'!$E$12,IF(K17="修改",I17*'模板使用说明&基础参数'!$E$6*'模板使用说明&基础参数'!$E$11,I17*'模板使用说明&基础参数'!$E$6*'模板使用说明&基础参数'!$E$10)),IF(K17="删除",I17*'模板使用说明&基础参数'!$E$7*'模板使用说明&基础参数'!$E$12,IF(K17="修改",I17*'模板使用说明&基础参数'!$E$7*'模板使用说明&基础参数'!$E$11,I17*'模板使用说明&基础参数'!$E$7*'模板使用说明&基础参数'!$E$10))))) -> 1.0666667
... A799: 794 | B799: 产商品中心 | C799: 营销活动验证 | D799: 营销活动信息核查 | E799: 营销活动信息核查 | F799: 作为业务人员，当需要新增终端营销活动核查信息时，能够通过此功能新增终端营销活动核查信息，以便于及时配置营销活动相关数据。本次涉及调整修改内容为新增终端营销活动核查信息新增处理逻辑，支持编号、名称、类型、状态、操作人员等内容的录入。 | G799: 终端营销活动核查信息新增 | H799: EI | I799: =IF(H799="ILF",IF($C$1="预估功能点",'模板使用说明&基础参数'!$E$15,7),IF(H799="EIF",IF($C$1="预估功能点",'模板使用说明&基础参数'!$E$16,5),IF(H799="EI",IF($C$1="预估功能点",'模板使用说明&基础参数'!$E$17,'模板使用说明&基础参数'!$E$24),IF(H799="EO",IF($C$1="预估功能点",'模板使用说明&基础参数'!$E$18,'模板使用说明&基础参数'!$E$25),IF(H799="EQ",IF($C$1="预估功能点",'模板使用说明&基础参数'!$E$19,'模板使用说明&基础参数'!$E$26),""))))) -> 4 | J799: 高 | K799: 修改 | L799: =IF(I799="","",IF(J799="高",IF(K799="删除",I799*'模板使用说明&基础参数'!$E$5*'模板使用说明&基础参数'!$E$12,IF(K799="修改",I799*'模板使用说明&基础参数'!$E$5*'模板使用说明&基础参数'!$E$11,I799*'模板使用说明&基础参数'!$E$5*'模板使用说明&基础参数'!$E$10)),IF(J799="中",IF(K799="删除",I799*'模板使用说明&基础参数'!$E$6*'模板使用说明&基础参数'!$E$12,IF(K799="修改",I799*'模板使用说明&基础参数'!$E$6*'模板使用说明&基础参数'!$E$11,I799*'模板使用说明&基础参数'!$E$6*'模板使用说明&基础参数'!$E$10)),IF(K799="删除",I799*'模板使用说明&基础参数'!$E$7*'模板使用说明&基础参数'!$E$12,IF(K799="修改",I799*'模板使用说明&基础参数'!$E$7*'模板使用说明&基础参数'!$E$11,I799*'模板使用说明&基础参数'!$E$7*'模板使用说明&基础参数'!$E$10))))) -> 1.0666667

Sheet 开发费用估算
A1: 规模估算结果（单位：功能点） | C1: =ROUND(规模估算!L3,2) -> 977.33
A2: 规模变更调整因子取值 | C2: =项目特征!D1 -> 1 | D2: =项目特征!C1 -> 项目完成及运维阶段
A3: 调整后规模（单位：功能点） | C3: =ROUND(C1*C2,2) -> 977.33
A4: 基准生产率（单位：人时/功能点） | C4: =IFERROR(ROUND(C5*0.8,2),"") -> 9.11 | D4: ="电信行业"&项目特征!C2&"基准生产率乐观值" -> 电信行业电信类系统基准生产率乐观值
C5: =项目特征!D2*1.06 -> 11.3844 | D5: ="电信行业"&项目特征!C2&"基准生产率中位值" -> 电信行业电信类系统基准生产率中位值
C6: =IFERROR(ROUND(C5*1.2,2),"") -> 13.66 | D6: ="电信行业"&项目特征!C2&"基准生产率悲观值" -> 电信行业电信类系统基准生产率悲观值
A7: 未调整工作量（单位：人天） | C7: =IFERROR(ROUND(C3*C4/8,2),"") -> 1112.93 | D7: 下限
C8: =IFERROR(ROUND(C3*C5/8,2),"") -> 1390.79 | D8: 中值
C9: =IFERROR(ROUND(C3*C6/8,2),"") -> 1668.79 | D9: 上限
A10: 调整因子 | B10: 质量特性 | C10: =1+0.025*SUM(项目特征!D3:项目特征!D6) -> 1 | D10: 无特别限定
B11: 完整性级别 | C11: =项目特征!D7 -> 1 | D11: 无特别限定
B12: 开发语言 | C12: =项目特征!D8 -> 1 | D12: 无特别限定
B13: 开发团队背景 | C13: =项目特征!D9 -> 0.8 | D13: =项目特征!C9 -> 为本行业开发过类似的软件
B14: 规格化系数 | C14: =IF(ISBLANK(C25),1,C18/C25) -> 1 | D14: 根据行业基准数据和合同约定的人力费率进行规格化处理
A15: 调整后工作量（单位：人天） | C15: =IFERROR(C7*C$10*C$11*C$12*C$13*C$14,"") -> 890.344 | D15: 下限
C16: =IFERROR(C8*C$10*C$11*C$12*C$13*C$14,"") -> 1112.632 | D16: 中值
C17: =IFERROR(C9*C$10*C$11*C$12*C$13*C$14,"") -> 1335.032 | D17: 上限
A18: 人力基准单价（单位：元/人天） | C18: =ROUND(25922/21.75,2) -> 1191.82 | D18: 2023年中国软件行业基准数据成都地区人力费率，不包含直接非人力成本
A19: 基准报价（单位：元） （不包含直接非人力成本） | C19: =IFERROR(IF(ISBLANK(C$25),ROUND(C15*C$18,2),ROUND(C15*C$25,2)),"") -> 1061129.8 | D19: 下限
C20: =IFERROR(IF(ISBLANK(C$25),ROUND(C16*C$18,2),ROUND(C16*C$25,2)),"") -> 1326057.1 | D20: 中值
C21: =IFERROR(IF(ISBLANK(C$25),ROUND(C17*C$18,2),ROUND(C17*C$25,2)),"") -> 1591117.8 | D21: 上限
A22: 合同工作量（人天）
A23: 评估工作量（人天） | C23: =IF(ISBLANK(C22),"",MIN(C16,C22))
A24: 工作量核减率 | C24: =IFERROR((C22-C23)/C22,"")
A25: 合同人天单价（元/人天） | D25: 含税，如果合同未约定人天单价，则不填写
A26: 送审订单金额（元） 仅指软件开发部分的含税金额，不含集成等其他费用 | C26: 2915000 | D26: 单一来源采购项目类开发，为合同中的软件开发含税金额；集运中心分次送审的工单类合同，为每次送审订单金额（各次送审订单金额累计为合同金额）
A27: 浮动系数 | C27: 1 | D27: 根据内审会议结论确定的规则，新建、替换项目上浮10%，续建项目上浮5%，其他不上浮；上浮仅对2022年6月30日前签订合同的项目；
A28: 审定金额（元） | C28: =IF(ISBLANK(C26),ROUND(C20*C27,2),MIN(ROUND(C20*C27,2),C26)) -> 1326057.1 | D28: 含税
A29: 审减率 | C29: =IFERROR((C26-C28)/C26,"") -> 0.54509191

Sheet 模板使用说明&基础参数
A2: 本模板通常只填写白色区域；
A3: 填写顺序为：填写项目特征->规模估算->查看结果（“开发工作量估算”相关部分）
A4: 深灰 | B4: 模板固定部分，不得修改 | D4: 重用程度调整系数
A5: 浅灰 | B5: 模板固定部分，在必要时统一修改 | D5: 高 | E5: 0.33333333
A6: 绿色 | B6: 自动计算或引用数据，不得修改 | D6: 中 | E6: 0.66666667
A7: 白色 | B7: 需填写或修改内容 | D7: 低 | E7: 1
D9: 修改类型调整系数 | G9: 应用类型 | H9: 描述 | I9: 调整因子
D10: 新增 | E10: 1 | G10: 电信类系统 | H10: B域系统：BOSS系统、CRM系统、BOMC业务支撑、CMOP系统、渠道酬金平台、清欠系统、客服系统、短信营业厅、网上商城系统等 O域系统：监控系统、网管系统、综合资源管理系统、服务保障系统等 | I10: 10.74
D11: 修改 | E11: 0.8 | G11: 非电信类系统 | H11: M域系统：项目管理系统、人力资源系统、全面预算系统、合同管理、绩效考核系统、综合事务管理系统、供应链管理系统、ERP等 其他：ITSM、大数据等 | I11: 8.7
D12: 删除 | E12: 0.2
D14: 预估功能点
D15: ILF | E15: 35
D16: EIF | E16: 15
D17: EI
D18: EO
D19: EQ | G19: 调整因子 | H19: 判断标准 | I19: 调整因子
G20: 分布式处理 | H20: 没有明示对分布式处理的需求事项 | I20: -1
D21: 估算功能点 | H21: 通过网络进行客户端/服务器及网络基础应用分布处理和传输 | I21: 0
D22: ILF | E22: 10 | H22: 通过特别的设计保证在多个服务器及处理器上同时相互执行应用中的处理功能 | I22: 1
D23: EIF | E23: 7 | G23: 性能 | H23: 没有明示对性能的特别需求事项或仅需提供基本性能 | I23: -1
D24: EI | E24: 4 | H24: 应答时间或处理率对高峰时间或所有业务时间来说都很重要，存在对连动系统结束处理时间的限制 | I24: 0
D25: EO | E25: 5 | H25: 为满足性能需求事项，要求设计阶段开始进行性能分析，或在设计、开发阶段使用分析工具 | I25: 1
D26: EQ | E26: 4 | G26: 可靠性 | H26: 没有明示对可靠性的特别需求事项或仅需提供基本的可靠性 | I26: -1
H27: 发生故障时带来较多不便或经济损失 | I27: 0
H28: 发生故障时造成重大经济损失或有生命危害 | I28: 1
G29: 多重站点 | H29: 在相同的硬件或软件环境下运行 | I29: -1
H30: 在设计阶段需要考虑不同站点的相似硬件或软件环境下运行需求 | I30: 0
H31: 在设计阶段需要考虑不同站点的不同硬件或软件环境下运行需求 | I31: 1
H34: 开发语言 | I34: 调整因子
H35: C及其他同级别语言/平台 | I35: 1.5
H36: JAVA、C++、C#及其他同级别语言/平台 | I36: 1
H37: PowerBuilder、ASP及其他同级别语言/平台 | I37: 0.6
H40: 开发团队背景 | I40: 调整因子
H41: 为本行业开发过类似的软件 | I41: 0.8
H42: 为其他行业开发过类似的软件，或为本行业开发过不同但相关的软件 | I42: 1
H43: 没有同类软件及本行业相关软件开发背景 | I43: 1.2
H45: 完整性级别 | I45: 调整因子
H46: 没有明确的完整性级别或等级为C/D | I46: 1
H47: 完整性级别为A/B同时为达成完整性级别要求采取了特殊的设计及实现方式 | I47: 1.1
H48: 完整性级别为A同时为达成完整性级别要求在软件开发全生命周期均采取了特定、明确的措施 | I48: 1.3
...

Sheet 其他特殊规则
A1: 定制规则
A2: 1.经局方三域沟通，对于增加水印、埋点等单一规则影响到多个事务功能的情况，进行功能点评估时最多正常评估40个功能点，超过40个以上的部分按50%来折算评估。即：公共功能的修改影响到多个事务功能时，最多计正常计40个功能点，事务功能修改计数结果超出部分按50%折算。
A3: 举例：如果是100个页面加水印，40个页面正常算，另外60个等效成30个，共计70个的等效页面来算。
